{
 "cells": [
  {
   "cell_type": "code",
   "execution_count": 1,
   "metadata": {},
   "outputs": [
    {
     "data": {
      "text/plain": [
       "True"
      ]
     },
     "execution_count": 1,
     "metadata": {},
     "output_type": "execute_result"
    }
   ],
   "source": [
    "from dotenv import load_dotenv\n",
    "\n",
    "load_dotenv()"
   ]
  },
  {
   "cell_type": "code",
   "execution_count": 2,
   "metadata": {},
   "outputs": [
    {
     "name": "stdout",
     "output_type": "stream",
     "text": [
      "ClearML Task: created new task id=3ce4cdbcca954f3ea9789c547c3c14fc\n",
      "2024-12-06 00:45:24,343 - clearml.Task - INFO - Storing jupyter notebook directly as code\n",
      "ClearML results page: http://localhost:8080/projects/7d8fe7e1a1b248fe900b932fd7c04b67/experiments/3ce4cdbcca954f3ea9789c547c3c14fc/output/log\n"
     ]
    },
    {
     "name": "stdout",
     "output_type": "stream",
     "text": [
      "ClearML Monitor: Could not detect iteration reporting, falling back to iterations as seconds-from-start\n"
     ]
    },
    {
     "name": "stderr",
     "output_type": "stream",
     "text": [
      "Retrying (Retry(total=237, connect=237, read=240, redirect=240, status=240)) after connection broken by 'NewConnectionError('<urllib3.connection.HTTPConnection object at 0x7fc20f841420>: Failed to establish a new connection: [Errno 111] Connection refused')': /v2.23/tasks.get_all\n",
      "Retrying (Retry(total=237, connect=237, read=240, redirect=240, status=240)) after connection broken by 'NewConnectionError('<urllib3.connection.HTTPConnection object at 0x7fc1dda48820>: Failed to establish a new connection: [Errno 111] Connection refused')': /v2.23/events.add_batch\n",
      "Retrying (Retry(total=237, connect=237, read=240, redirect=240, status=240)) after connection broken by 'NewConnectionError('<urllib3.connection.HTTPConnection object at 0x7fc1dc434eb0>: Failed to establish a new connection: [Errno 111] Connection refused')': /v2.23/events.add_batch\n",
      "Retrying (Retry(total=236, connect=236, read=240, redirect=240, status=240)) after connection broken by 'NewConnectionError('<urllib3.connection.HTTPConnection object at 0x7fc20f8417e0>: Failed to establish a new connection: [Errno 111] Connection refused')': /v2.23/tasks.get_all\n",
      "Retrying (Retry(total=236, connect=236, read=240, redirect=240, status=240)) after connection broken by 'NewConnectionError('<urllib3.connection.HTTPConnection object at 0x7fc1dda48550>: Failed to establish a new connection: [Errno 111] Connection refused')': /v2.23/events.add_batch\n",
      "Retrying (Retry(total=236, connect=236, read=240, redirect=240, status=240)) after connection broken by 'NewConnectionError('<urllib3.connection.HTTPConnection object at 0x7fc1dda48a30>: Failed to establish a new connection: [Errno 111] Connection refused')': /v2.23/events.add_batch\n",
      "Retrying (Retry(total=235, connect=235, read=240, redirect=240, status=240)) after connection broken by 'NewConnectionError('<urllib3.connection.HTTPConnection object at 0x7fc20f841240>: Failed to establish a new connection: [Errno 111] Connection refused')': /v2.23/tasks.get_all\n",
      "Retrying (Retry(total=235, connect=235, read=240, redirect=240, status=240)) after connection broken by 'NewConnectionError('<urllib3.connection.HTTPConnection object at 0x7fc1dda4bd90>: Failed to establish a new connection: [Errno 111] Connection refused')': /v2.23/events.add_batch\n",
      "Retrying (Retry(total=235, connect=235, read=240, redirect=240, status=240)) after connection broken by 'NewConnectionError('<urllib3.connection.HTTPConnection object at 0x7fc1dda4be80>: Failed to establish a new connection: [Errno 111] Connection refused')': /v2.23/events.add_batch\n",
      "Retrying (Retry(total=234, connect=234, read=240, redirect=240, status=240)) after connection broken by 'NewConnectionError('<urllib3.connection.HTTPConnection object at 0x7fc20f8418d0>: Failed to establish a new connection: [Errno 111] Connection refused')': /v2.23/tasks.get_all\n",
      "Retrying (Retry(total=234, connect=234, read=240, redirect=240, status=240)) after connection broken by 'NewConnectionError('<urllib3.connection.HTTPConnection object at 0x7fc1dda48cd0>: Failed to establish a new connection: [Errno 111] Connection refused')': /v2.23/events.add_batch\n",
      "Retrying (Retry(total=234, connect=234, read=240, redirect=240, status=240)) after connection broken by 'NewConnectionError('<urllib3.connection.HTTPConnection object at 0x7fc1dda4aec0>: Failed to establish a new connection: [Errno 111] Connection refused')': /v2.23/events.add_batch\n",
      "Retrying (Retry(total=233, connect=233, read=240, redirect=240, status=240)) after connection broken by 'NewConnectionError('<urllib3.connection.HTTPConnection object at 0x7fc20f842ad0>: Failed to establish a new connection: [Errno 111] Connection refused')': /v2.23/tasks.get_all\n",
      "Retrying (Retry(total=233, connect=233, read=240, redirect=240, status=240)) after connection broken by 'NewConnectionError('<urllib3.connection.HTTPConnection object at 0x7fc1ddbeeec0>: Failed to establish a new connection: [Errno 111] Connection refused')': /v2.23/events.add_batch\n",
      "Retrying (Retry(total=233, connect=233, read=240, redirect=240, status=240)) after connection broken by 'NewConnectionError('<urllib3.connection.HTTPConnection object at 0x7fc1ddbef340>: Failed to establish a new connection: [Errno 111] Connection refused')': /v2.23/events.add_batch\n",
      "Retrying (Retry(total=232, connect=232, read=240, redirect=240, status=240)) after connection broken by 'NewConnectionError('<urllib3.connection.HTTPConnection object at 0x7fc20f842980>: Failed to establish a new connection: [Errno 111] Connection refused')': /v2.23/tasks.get_all\n",
      "Retrying (Retry(total=232, connect=232, read=240, redirect=240, status=240)) after connection broken by 'NewConnectionError('<urllib3.connection.HTTPConnection object at 0x7fc1dda4a590>: Failed to establish a new connection: [Errno 111] Connection refused')': /v2.23/events.add_batch\n",
      "Retrying (Retry(total=232, connect=232, read=240, redirect=240, status=240)) after connection broken by 'NewConnectionError('<urllib3.connection.HTTPConnection object at 0x7fc1ddbed330>: Failed to establish a new connection: [Errno 111] Connection refused')': /v2.23/events.add_batch\n"
     ]
    }
   ],
   "source": [
    "import os\n",
    "from clearml import Task\n",
    "task = Task.init(project_name=\"my project\",task_name=\"my task\")"
   ]
  }
 ],
 "metadata": {
  "kernelspec": {
   "display_name": "Python 3",
   "language": "python",
   "name": "python3"
  },
  "language_info": {
   "codemirror_mode": {
    "name": "ipython",
    "version": 3
   },
   "file_extension": ".py",
   "mimetype": "text/x-python",
   "name": "python",
   "nbconvert_exporter": "python",
   "pygments_lexer": "ipython3",
   "version": "3.10.12"
  }
 },
 "nbformat": 4,
 "nbformat_minor": 2
}
